<robot  name="arm">

<gazebo>
  <plugin name="gazebo_ros_control" filename="libgazebo_ros_control.so">
 <!--   <robotNamespace>/mico_simplified</robotNamespace>
		<robotSimType>gazebo_ros_control/DefaultRobotHWSim</robotSimType>--> 
  </plugin>
</gazebo>

<!--
 Trying to get thing to not flail START
  <dynamics damping="0.0" friction="0.0"/>

  <physics type="ode">
  <gravity xyz="0 0 -9.8"/>
  <ode>
    <solver type="quick" dt="0.0001" iters="1000" sor="1.3"/>
    <constraints cfm="0.0" erp="0.1" contact_max_correcting_vel="10.0" contact_surface_layer="0.001"/>
  </ode>
</physics>
-->

<!--PLANO BASE -->
  <link name="world"/>
   <joint name="fixed" type="fixed">
    <parent link="world"/>
    <child link="support_box"/>
  </joint>

  <link name="support_box">
  <inertial>
      <origin  xyz="0.0 0.0 0.06"  rpy="0 0 0" />
      <mass  value="0.8" />
      <inertia ixx="0.016667333" ixy="0.0" ixz="0.00"  iyy="0.016667333"  iyz="0.0" izz="0.016667333" />
    </inertial>
    <visual>
      <origin rpy="0 0 0" xyz="0 0 0.06"/>
      <geometry>
        <box size=".5 .5 .01"/>
        <!--making it slightly bigger in x and z direction-->
      </geometry>
      <material name="Black"/>
    </visual>
    <collision>
      <origin rpy="0 0 0" xyz="0 0 0.06"/>
      <geometry>
        <box size=".5 .5 .01"/>
        <!--making it slightly bigger in x and z direction-->
      </geometry>
    </collision>
  </link>
  
   <!--EARMBASE-->
   <joint name="earm_joint_base" type="fixed">
    <parent link="support_box"/>
    <child link="base_link"/>
     <origin  xyz="0.5 -0.3 0.65"  rpy="0 0 0" />
  </joint>

  <link  name="base_link">
    <inertial>
      <origin  xyz="0.0 0.0 0.0"  rpy="0 0 0" />
      <mass  value="0.01" />
      <inertia ixx="0.0001" ixy="0.0" ixz="0.000"  iyy="0.0001"  iyz="0.0" izz="0.0001" />
    </inertial>
    <visual>
      <origin  xyz="0 0 0.0"  rpy="0 0 0" />
      <geometry>
        <mesh filename="package://arm/meshes/mount.stl" scale="0.01 0.01 0.01"/>
      </geometry>
     </visual>
    <collision>
      <origin  xyz="0 0 0.0"  rpy="0 0 0" />
      <geometry>
        <mesh filename="package://arm/meshes/mount.stl" scale="0.01 0.01 0.01" />
      </geometry>
    </collision>
  </link>
  
  <!--PRIMERMotorBASE-->
   <joint name="motor_base" type="fixed">
    <parent link="base_link"/>
    <child link="motor_base"/>
     <origin  xyz="-0.5 0.3 0.2"  rpy="1.570796327 0 3.14159" />
  </joint>

  <link  name="motor_base">
    <inertial>
     <origin  xyz="0 0 0.0"  rpy="0 0 0" />
      <mass  value="0.01" />
      <inertia ixx="0.0001" ixy="0.0" ixz="0.000"  iyy="0.0001"  iyz="0.0" izz="0.0001" />
    </inertial>
    <visual>
      <origin  xyz="0 0 0.0"  rpy="0 0 0" />
      <geometry>     
        <mesh filename="package://arm/meshes/ax12_box.stl" scale="0.01 0.01 0.01"/>
      </geometry>         
    </visual>
    <collision>
    <origin  xyz="0 0 0.0"  rpy="0 0 0" />
      <geometry>
        <mesh filename="package://arm/meshes/ax12_box.stl" scale="0.01 0.01 0.01" />
      </geometry>
    </collision>
  </link>
  
  <!--ACOPLE PLANO PRIMER JOINT-->
   <joint name="joint1" type="revolute">
    <parent link="motor_base"/>
    <child link="acople_plano"/>
     <origin  xyz="-0.0 0.21 0.0"  rpy="1.570795 0 0" />
     <axis  xyz="0 0 -1" />
    <limit  lower="-1.570795" upper="1.570795" effort="30"  velocity="1.57" />
  </joint>
  
 <link  name="acople_plano">
    <inertial>
     <origin  xyz="0 0 0.0"  rpy="0 0 0" />
      <mass  value="0.01" />
      <inertia ixx="0.0001" ixy="0.0" ixz="0.000"  iyy="0.0001"  iyz="0.0" izz="0.0001" />
    </inertial>
    <visual>
      <origin  xyz="0 0 0.0"  rpy="0 0 0" />
      <geometry>     
        <mesh filename="package://arm/meshes/F3.stl" scale="0.01 0.01 0.01"/>
      </geometry>   
    </visual>
    <collision>
    <origin  xyz="0 0 0.0"  rpy="0 0 0" />
      <geometry>
        <mesh filename="package://arm/meshes/F3.stl" scale="0.01 0.01 0.01" />
      </geometry>
    </collision>
  </link>
  
    <!--SEGUNDOMotor-->
   <joint name="motor_2" type="fixed">
    <parent link="acople_plano"/>
    <child link="motor2"/>
     <origin  xyz="-0.0 0.0 -0.41"  rpy="3.14159 0 3.14159 " />
  </joint>

  <link  name="motor2">
    <inertial>
     <origin  xyz="0 0 0.0"  rpy="0 0 0" />
      <mass  value="0.01" />
      <inertia ixx="0.0001" ixy="0.0" ixz="0.000"  iyy="0.0001"  iyz="0.0" izz="0.0001" />
    </inertial>
    <visual>
      <origin  xyz="0 0 0.0"  rpy="0 0 0" />
      <geometry>     
        <mesh filename="package://arm/meshes/ax12_box.stl" scale="0.01 0.01 0.01"/>
      </geometry>         
    </visual>
    <collision>
    <origin  xyz="0 0 0.0"  rpy="0 0 0" />
      <geometry>
        <mesh filename="package://arm/meshes/ax12_box.stl" scale="0.01 0.01 0.01" />
      </geometry>
    </collision>
  </link>
  
  
   <!--ACOPLE BRACKET LARGO SEGUNDA JOINT-->
   <joint name="joint2" type="revolute">
    <parent link="motor2"/>
    <child link="acople_bracket_l"/>
     <origin  xyz="-0.0 0.0 0.0"  rpy="0 0 0" />
     <axis  xyz="0 1 0" />
    <limit  lower="-1.570795" upper="1.570795" effort="30"  velocity="1.57" />
  </joint>
  
 <link  name="acople_bracket_l">
    <inertial>
     <origin  xyz="0 0 0.0"  rpy="0 0 0" />
      <mass  value="0.01" />
      <inertia ixx="0.0001" ixy="0.0" ixz="0.000"  iyy="0.0001"  iyz="0.0" izz="0.0001" />
    </inertial>
    <visual>
      <origin  xyz="0 0 0.0"  rpy="0 0 0" />
      <geometry>     
        <mesh filename="package://arm/meshes/F4.stl" scale="0.01 0.01 0.01"/>
      </geometry>   
    </visual>
    <collision>
    <origin  xyz="0 0 0.0"  rpy="0 0 0" />
      <geometry>
        <mesh filename="package://arm/meshes/F4.stl" scale="0.01 0.01 0.01" />
      </geometry>
    </collision>
  </link>
  
      <!--TERCERMotor-->
   <joint name="motor_3" type="fixed">
    <parent link="acople_bracket_l"/>
    <child link="motor5"/>
     <origin  xyz="-0.0 0.0 0.5"  rpy="3.14159 0 3.14159 " />
  </joint>

  <link  name="motor5">
    <inertial>
     <origin  xyz="0 0 0.0"  rpy="0 0 0" />
      <mass  value="0.01" />
      <inertia ixx="0.0001" ixy="0.0" ixz="0.000"  iyy="0.0001"  iyz="0.0" izz="0.0001" />
    </inertial>
    <visual>
      <origin  xyz="0 0 0.0"  rpy="0 0 0" />
      <geometry>     
        <mesh filename="package://arm/meshes/ax12_box.stl" scale="0.01 0.01 0.01"/>
      </geometry>         
    </visual>
    <collision>
    <origin  xyz="0 0 0.0"  rpy="0 0 0" />
      <geometry>
        <mesh filename="package://arm/meshes/ax12_box.stl" scale="0.01 0.01 0.01" />
      </geometry>
    </collision>
  </link>
  
  
  
  <transmission name="tran6">
    <type>transmission_interface/SimpleTransmission</type>
    <joint name="joint1">
     <hardwareInterface>PositionJointInterface</hardwareInterface>
     </joint>
    <actuator name="motor6">     
      <mechanicalReduction>1</mechanicalReduction>
    </actuator>
  </transmission>
  


   
</robot>


