<?xml version="1.0"?>
<robot name="ve026a" xmlns:xacro="http://ros.org/wiki/xacro">
	<link name="base_link">
		<visual>
			<geometry>
				<mesh filename="package://denso_ve026a/meshes/base.stl" scale="1 1 1"/>
			</geometry>
			<origin xyz="-0.000283 -0.001865 0"/>
			<material name="base_link">
	        	<color rgba="0.3 0.3 0.3 1"/>
			</material>
    	</visual>
      	<inertial>
      		<mass value="0.1"/>
      		<inertia ixx="1.0" ixy="0.0" ixz="0.0" iyy="1.0" iyz="0.0" izz="1.0"/>
    	</inertial>
  	</link>
	
	<link name="link0">
		<visual>
		  	<geometry>
		    	<mesh filename="package://denso_ve026a/meshes/l0.stl" scale="1 1 1"/>
		  	</geometry>
		  	<origin xyz="-0.000283 -0.001865 0"/>
		  	<material name="link">
		    	<color rgba="0.8 0.8 0.8 1"/>
		  	</material>
		</visual>
      	<inertial>
      		<mass value="0.1"/>
      		<inertia ixx="1.0" ixy="0.0" ixz="0.0" iyy="1.0" iyz="0.0" izz="1.0"/>
    	</inertial>
	</link>
	
	
	<joint name="J0" type="fixed">
		<axis xyz="0 0 1"/>
		<origin rpy="0 0 0" xyz="0.0 0.0 0.0"/>
		<parent link="base_link"/>
		<child link="link0"/>
	</joint>
	
	<link name="link1">
    	<visual>
      		<geometry>
		    	<mesh filename="package://denso_ve026a/meshes/l1.stl" scale="1 1 1"/>
			</geometry>
			<origin xyz="-0.000283 -0.001865 0"/>
			<material name="joint">
        		<color rgba="0.5 0.5 0.5 1"/>
      		</material>
    	</visual>
      	<inertial>
      		<mass value="0.1"/>
      		<inertia ixx="1.0" ixy="0.0" ixz="0.0" iyy="1.0" iyz="0.0" izz="1.0"/>
    	</inertial>
  	</link>
	<joint name="J1" type="revolute">
    	<axis xyz="0 0 1"/>
    	<limit effort="1000.0" lower="-1.39626" upper="1.83259" velocity="3.0"/>
    	<origin rpy="0 0 0" xyz="0.0 0.0 0.0"/>
    	<parent link="link0"/>
    	<child link="link1"/>
  	</joint>
  	
  	<link name="link2">
    	<visual>
      		<geometry>
				<mesh filename="package://denso_ve026a/meshes/l2.stl" scale="1 1 1"/>
			</geometry>
			<origin xyz="-0.000283 -0.001865 -0.130"/>
			<material name="link"/>
    	</visual>
      	<inertial>
      		<mass value="0.1"/>
      		<inertia ixx="1.0" ixy="0.0" ixz="0.0" iyy="1.0" iyz="0.0" izz="1.0"/>
    	</inertial>
  	</link>
  
  	<joint name="J2" type="revolute">
    	<axis xyz="0 1 0"/>
    	<limit effort="1000.0" lower="-0.61086" upper="1.57075" velocity="3.0"/>
    	<origin rpy="0 0 0" xyz="0.0 0.0 0.130"/>
    	<parent link="link1"/>
    	<child link="link2"/>
  	</joint>
  	
  	<link name="link3">
    	<visual>
      		<geometry>
				<mesh filename="package://denso_ve026a/meshes/l3.stl" scale="1 1 1"/>
			</geometry>
			<origin xyz="-0.000283 -0.001865 -0.230"/>
			<material name="joint"/>
    	</visual>
      	<inertial>
      		<mass value="0.1"/>
      		<inertia ixx="1.0" ixy="0.0" ixz="0.0" iyy="1.0" iyz="0.0" izz="1.0"/>
    	</inertial>
  	</link>
 	
 	<joint name="J3" type="revolute">
	    <axis xyz="0 1 0"/>
    	<limit effort="1000.0" lower="-1.30899" upper="2.35619" velocity="3.0"/>
    	<origin rpy="0 0 0" xyz="0.0 0.0 0.100"/>
	    <parent link="link2"/>
    	<child link="link3"/>
	</joint>
	
	<link name="link4">
    	<visual>
    		<geometry>
				<mesh filename="package://denso_ve026a/meshes/l4.stl" scale="1 1 1"/>
			</geometry>
			<origin xyz="-0.000283 -0.001865 -0.248"/>
			<material name="link"/>
    	</visual>
      	<inertial>
      		<mass value="0.1"/>
      		<inertia ixx="1.0" ixy="0.0" ixz="0.0" iyy="1.0" iyz="0.0" izz="1.0"/>
    	</inertial>
	</link>
  
	<joint name="J4" type="revolute">
		<axis xyz="0 0 1"/>
		<limit effort="1000.0" lower="-2.44346" upper="2.44346" velocity="3.0"/>
		<origin rpy="0 0 0" xyz="0.0 0.0 0.018"/>
		<parent link="link3"/>
    	<child link="link4"/>
	</joint>

	<link name="link5">
		<visual>
			<geometry>
				<mesh filename="package://denso_ve026a/meshes/l5.stl" scale="1 1 1"/>
			</geometry>
			<origin xyz="-0.000283 -0.001865 -0.320"/>
			<material name="joint"/>
		</visual>
      	<inertial>
      		<mass value="0.1"/>
      		<inertia ixx="1.0" ixy="0.0" ixz="0.0" iyy="1.0" iyz="0.0" izz="1.0"/>
    	</inertial>
	</link>
 	
	<joint name="J5" type="revolute">
		<axis xyz="0 1 0"/>
		<limit effort="1000.0" lower="-1.57075" upper="1.83259" velocity="3.0"/>
		<origin rpy="0 0 0" xyz="0.0 0.0 0.075"/>
		<parent link="link4"/>
		<child link="link5"/>
	</joint>
	
	<link name="link6">
		<visual>
			<geometry>
				<mesh filename="package://denso_ve026a/meshes/l6.stl" scale="1 1 1"/>
			</geometry>
			<origin xyz="-0.000283 -0.001865 -0.338"/>
			<material name="link"/>
		</visual>
     	<inertial>
      		<mass value="0.1"/>
      		<inertia ixx="1.0" ixy="0.0" ixz="0.0" iyy="1.0" iyz="0.0" izz="1.0"/>
    	</inertial>
	</link>
  
	<joint name="J6" type="revolute">
		<axis xyz="0 0 1"/>
		<limit effort="1000.0" lower="-2.44346" upper="2.44346" velocity="3.0"/>
		<origin rpy="0 0 0" xyz="0.0 0.0 0.018"/>
		<parent link="link5"/>
		<child link="link6"/>
	</joint>
	
	<link name="link7">
		<visual>
			<geometry>
				<cylinder length="0.010" radius="0.005"/>
			</geometry>
			<origin xyz="0 0 0"/>
			<material name="joint"/>
		</visual>	
      	<inertial>
      		<mass value="0.1"/>
      		<inertia ixx="1.0" ixy="0.0" ixz="0.0" iyy="1.0" iyz="0.0" izz="1.0"/>
    	</inertial>
	</link>

	<joint name="J7" type="revolute">
		<axis xyz="0 0 1"/>
		<limit effort="1000.0" lower="-0.63633" upper="0.43633" velocity="3.0"/> 
		<origin rpy="0 0 0" xyz="0.0 0.0 0.068"/>
		<parent link="link6"/>
		<child link="link7"/>
	</joint>
	
<!--  
  	
	

  
	
  
	<link name="link5">
		<visual>
			<geometry>
				<box size="0.050 0.030 0.068"/>
			</geometry>
			<origin xyz="0 0 0.034"/>
			<material name="link"/>
		</visual>
		<collision>
			<geometry>
				<box size="0.050 0.030 0.068"/>
			</geometry>
			<origin xyz="0 0 0.034"/>
      	</collision>
      	<inertial>
      		<mass value="0.1"/>
      		<inertia ixx="1.0" ixy="0.0" ixz="0.0" iyy="1.0" iyz="0.0" izz="1.0"/>
    	</inertial>
	</link>
  
	<joint name="J6" type="revolute">
		<axis xyz="0 0 1"/>
		<limit effort="1000.0" lower="-2.44346" upper="2.44346" velocity="3.0"/>
		<origin rpy="0 0 0" xyz="0.0 0.0 0.020"/>
		<parent link="link4"/>
		<child link="link5"/>
	</joint>

	<link name="link6">
		<visual>
			<geometry>
				<box size="0.050 0.030 0.010"/>
			</geometry>
			<origin xyz="0 0 0.005"/>
			<material name="joint"/>
		</visual>
		<collision>
			<geometry>
				<box size="0.050 0.030 0.010"/>
			</geometry>
			<origin xyz="0 0 0.005"/>
      	</collision>
      	<inertial>
      		<mass value="0.1"/>
      		<inertia ixx="1.0" ixy="0.0" ixz="0.0" iyy="1.0" iyz="0.0" izz="1.0"/>
    	</inertial>
	</link>

	<joint name="J7" type="fixed">
		<axis xyz="0 0 1"/>
		<limit effort="1000.0" lower="-1.30899" upper="0.43633" velocity="3.0"/> 
		<origin rpy="0 0 0" xyz="0.0 0.0 0.068"/>
		<parent link="link5"/>
		<child link="link6"/>
	</joint>

	<link name="gripper_left">
		<visual>
			<geometry>
				<box size="0.020 0.002 0.030"/>
			</geometry>
			<origin xyz="0 0 0.025"/>
			<material name="gripper">
				<color rgba="0.8 0.8 0.3 1"/>
			</material>
		</visual>
		<collision>
			<geometry>
				<box size="0.020 0.002 0.030"/>
			</geometry>
			<origin xyz="0 0 0.025"/>
      	</collision>
      	<inertial>
      		<mass value="0.1"/>
      		<inertia ixx="1.0" ixy="0.0" ixz="0.0" iyy="1.0" iyz="0.0" izz="1.0"/>
    	</inertial>
	</link>

	<joint name="J7_left" type="prismatic">
		<axis xyz="0 1 0"/>
		<limit effort="1000.0" lower="0.013" upper="0.0215" velocity="3.0"/>
		<origin rpy="0 0 0" xyz="0.0 0.0 0.0"/>
		<parent link="link6"/>
		<child link="gripper_left"/>
	</joint>

	<link name="gripper_right">
		<visual>
			<geometry>
				<box size="0.020 0.002 0.030"/>
			</geometry>
			<origin xyz="0 0 0.025"/>
			<material name="gripper"/>
		</visual>
		<collision>
			<geometry>
				<box size="0.020 0.002 0.030"/>
			</geometry>
			<origin xyz="0 0 0.025"/>
      	</collision>
      	<inertial>
      		<mass value="0.1"/>
      		<inertia ixx="1.0" ixy="0.0" ixz="0.0" iyy="1.0" iyz="0.0" izz="1.0"/>
    	</inertial>
	</link>

	<joint name="J7_right" type="prismatic">
		<axis xyz="0 1 0"/>
		<limit effort="1000.0" lower="-0.013" upper="-0.0215" velocity="3.0"/>
		<origin rpy="0 0 0" xyz="0.0 0.0 0.0"/>
		<parent link="link6"/>
		<child link="gripper_right"/>
	</joint>
-->
</robot>
